<?xml version="1.0" ?>
<!-- =================================================================================== -->
<!-- |    This document was autogenerated by xacro from /home/crosslab/local_workspaces/summer_school_ws/src/DRIMS_volterra/drims_dice_demo/xacro/robot_arm.urdf.xacro | -->
<!-- |    EDITING THIS FILE BY HAND IS NOT RECOMMENDED                                 | -->
<!-- =================================================================================== -->
<robot name="robot">
    <!-- <xacro:arg name="gripper_interface" default="hardware_interface/PositionJointInterface" /> -->
    <material name="Black">
        <color rgba="0.0 0.0 0.0 1.0" />
    </material>
    <material name="Blue">
        <color rgba="0.0 0.0 0.8 1.0" />
    </material>
    <material name="Green">
        <color rgba="0.0 0.8 0.0 1.0" />
    </material>
    <material name="Grey">
        <color rgba="0.5 0.5 0.5 1.0" />
    </material>
    <material name="Light_Grey">
        <color rgba="0.8 0.8 0.8 1.0" />
    </material>
    <material name="Ivory">
        <color rgba="1.0 1.0 0.94 1.0" />
    </material>
    <material name="Orange">
        <color rgba="1.0 0.4235294117647059 0.0392156862745098 1.0" />
    </material>
    <material name="Brown">
        <color rgba="0.8705882352941177 0.8117647058823529 0.7647058823529411 1.0" />
    </material>
    <material name="Red">
        <color rgba="0.8 0.0 0.0 1.0" />
    </material>
    <material name="White">
        <color rgba="1.0 1.0 1.0 1.0" />
    </material>
    <gazebo reference="base_link_table">
        <mu1>0.2</mu1>
        <mu2>0.1</mu2>
        <plugin name="gazebo_ros_control" filename="libgazebo_ros_control.so">
            <robotNamespace>/</robotNamespace>
        </plugin>
    </gazebo>
    <!-- 72 52 2 -->
    <!-- GoFa color -->
    <material name="gofa_color">
        <color rgba="0.792156862745098 0.819607843137255 0.933333333333333 1" />
    </material>
    <!-- World fixed joint -->
    <link name="world" />
    <!-- <material name="yellow">
            <color rgba="255.0 255.0 0.0 1"/>
        </material> -->
    <joint name="joint_table_robot" type="fixed">
        <origin rpy="0 0 0" xyz="0 0 0" />
        <parent link="world" />
        <child link="base_link_table" />
    </joint>
    <gazebo reference="base_link_table">
        <material>Gazebo/Grey</material>
    </gazebo>
    <link name="base_link_table">
        <contact>
            <lateral_friction value="1.0" />
        </contact>
        <inertial>
            <origin rpy="0 0 0" xyz="0 0 0" />
            <mass value=".0" />
            <inertia ixx="1" ixy="0" ixz="0" iyy="1" iyz="0" izz="1" />
        </inertial>
        <visual>
            <origin rpy="0 0 0" xyz="0 0 0.6" />
            <geometry>
                <mesh filename="package://drims_dice_demo/meshes/Extra/table.obj" scale="1.5 1 0.05" />
            </geometry>
            <!-- <material name="Gazebo/Yellow"/> -->
        </visual>
        <collision>
            <origin rpy="0 0 0" xyz="0 0 0.6" />
            <geometry>
                <mesh filename="package://drims_dice_demo/meshes/Extra/table.obj" scale="1.5 1 0.05" />
            </geometry>
            <!-- <material name="Gazebo/Yellow"/> -->
        </collision>
        <!-- <collision>
                <origin rpy="0 0 0" xyz="0 0 0.6"/>
                <geometry>
                    <box size="1.5 1 0.05"/>
                </geometry>
            </collision> -->
        <visual>
            <origin rpy="0 0 0" xyz="-0.65 -0.4 0.29" />
            <geometry>
                <mesh filename="package://drims_dice_demo/meshes/Extra/table.obj" scale="0.1 0.1 0.58" />
            </geometry>
            <!-- <material name="white">
                    <color rgba="1 1 1 1"/>
                </material>	  -->
        </visual>
        <visual>
            <origin rpy="0 0 0" xyz="-0.65 0.4 0.29" />
            <geometry>
                <mesh filename="package://drims_dice_demo/meshes/Extra/table.obj" scale="0.1 0.1 0.58" />
            </geometry>
            <!-- <material name="white">
                    <color rgba="1 1 1 1"/>
                </material>	  -->
        </visual>
        <visual>
            <origin rpy="0 0 0" xyz="0.65 -0.4 0.29" />
            <geometry>
                <mesh filename="package://drims_dice_demo/meshes/Extra/table.obj" scale="0.1 0.1 0.58" />
            </geometry>
            <!-- <material name="white">
                    <color rgba="1 1 1 1"/>
                </material>	  -->
        </visual>
        <visual>
            <origin rpy="0 0 0" xyz="0.65 0.4 0.29" />
            <geometry>
                <mesh filename="package://drims_dice_demo/meshes/Extra/table.obj" scale="0.1 0.1 0.58" />
            </geometry>
        </visual>
    </link>
    <joint name="joint_camera_stand_robot" type="fixed">
        <origin rpy="0 0 0" xyz="0.0 0.4 0.65" />
        <parent link="base_link_table" />
        <child link="base_link_camera_stand" />
    </joint>
    <link name="base_link_camera_stand">
        <inertial>
            <origin rpy="0 0 0" xyz="0 0 0" />
            <mass value="1.0" />
            <inertia ixx="1" ixy="0" ixz="0" iyy="1" iyz="0" izz="1" />
        </inertial>
        <visual>
            <origin rpy="0 0 0" xyz="0 0 0.44" />
            <geometry>
                <box size="0.04 0.04 0.88" />
            </geometry>
        </visual>
        <collision>
            <origin rpy="0 0 0" xyz="0 0 0.44" />
            <geometry>
                <box size="0.04 0.04 0.88" />
            </geometry>
        </collision>
    </link>
    <link name="camera_holder">
        <inertial>
            <origin rpy="0 0 0" xyz="0 0 0" />
            <mass value="1.0" />
            <inertia ixx="1" ixy="0" ixz="0" iyy="1" iyz="0" izz="1" />
        </inertial>
        <visual>
            <origin rpy="0 0 0" xyz="0 0 0.15" />
            <geometry>
                <box size="0.04 0.04 0.3" />
            </geometry>
        </visual>
        <collision>
            <origin rpy="0 0 0" xyz="0 0 0.15" />
            <geometry>
                <box size="0.1 0.1 0.3" />
            </geometry>
        </collision>
    </link>
    <joint name="joint_camera_holder" type="fixed">
        <origin rpy="1.5707963267948966 -1.5707963267948966 0" xyz="0.0 0.0 0.88" />
        <parent link="base_link_camera_stand" />
        <child link="camera_holder" />
    </joint>
    <link name="ext_camera_link">
        <visual>
            <origin rpy="0 0 0" xyz="0 0 0" />
            <geometry>
                <box size="0.01 0.01 0.01" />
            </geometry>
            <material name="Red" />
        </visual>
        <inertial>
            <mass value="1e-5" />
            <origin rpy="0 0 0" xyz="0 0 0" />
            <inertia ixx="1e-6" ixy="0" ixz="0" iyy="1e-6" iyz="0" izz="1e-6" />
        </inertial>
    </link>
    <joint name="joint_camera_link" type="fixed">
        <origin rpy="-1.5707963267948966 0 -3.14 " xyz="0.0 0.0 0.4" />
        <parent link="camera_holder" />
        <child link="ext_camera_link" />
    </joint>
    <gazebo reference="ext_camera_link">
        <sensor name="camera1" type="camera">
            <update_rate>5.0</update_rate>
            <camera name="head">
                <horizontal_fov>1.01</horizontal_fov>
                <image>
                    <width>1280</width>
                    <height>720</height>
                    <format>R8G8B8</format>
                </image>
                <clip>
                    <near>0.02</near>
                    <far>300</far>
                </clip>
                <noise>
                    <type>gaussian</type>
                    <!-- Noise is sampled independently per pixel on each frame.
                        That pixel's noise value is added to each of its color
                        channels, which at that point lie in the range [0,1]. -->
                    <mean>0.0</mean>
                    <stddev>0.007</stddev>
                </noise>
            </camera>
            <plugin filename="libgazebo_ros_camera.so" name="camera_controller">
                <alwaysOn>true</alwaysOn>
                <updateRate>5.0</updateRate>
                <cameraName>camera</cameraName>
                <imageTopicName>/oak/rgb/image_raw</imageTopicName>
                <cameraInfoTopicName>camera_info</cameraInfoTopicName>
                <frameName>ext_camera_link</frameName>
                <!-- <hackBaseline>0.07</hackBaseline> -->
                <distortionK1>0.000001</distortionK1>
                <distortionK2>0.000001</distortionK2>
                <distortionK3>0.000001</distortionK3>
                <distortionT1>0.000001</distortionT1>
                <distortionT2>0.000001</distortionT2>
            </plugin>
        </sensor>
    </gazebo>
    <joint name="joint_surface_robot" type="fixed">
        <origin rpy="0 0 0" xyz="-0.03 0.33 0.08" />
        <parent link="gofa_base_link" />
        <child link="base_link_surface" />
    </joint>
    <gazebo reference="base_link_surface">
        <material>Gazebo/Green</material>
    </gazebo>
    <link name="base_link_surface">
        <inertial>
            <origin rpy="0 0 0" xyz="0 0 0" />
            <mass value="1.0" />
            <inertia ixx="1" ixy="0" ixz="0" iyy="1" iyz="0" izz="1" />
        </inertial>
        <visual>
            <origin rpy="0 0 0" xyz="0 0 0" />
            <geometry>
                <box size="0.6 0.4 0.1" />
            </geometry>
        </visual>
        <collision>
            <origin rpy="0 0 0" xyz="0 0 0" />
            <geometry>
                <box size="0.6 0.4 0.1" />
            </geometry>
        </collision>
    </link>
    <!-- Choose between gofa and yumi_single_arm -->
    <!-- Base -->
    <joint name="base_link_table_to_gofa_base_link" type="fixed">
        <origin rpy="0 0 -1.57" xyz="-0.3 0 0.627" />
        <parent link="base_link_table" />
        <child link="gofa_base_link" />
    </joint>
    <link name="gofa_base_link">
        <inertial>
            <origin rpy="0 0 0" xyz="-0.0012013793465437 -0.000175191786981708 0.0862146007385352" />
            <mass value="3.50083457958494" />
            <inertia ixx="0.0153015257917955" ixy="-6.40155032892694E-05" ixz="-0.000276708687772683" iyy="0.0159333503953857" iyz="-3.98029144780725E-05" izz="0.0112162302268266" />
        </inertial>
        <visual>
            <origin rpy="0 0 0" xyz="0 0 0" />
            <geometry>
                <mesh filename="package://omnicore_description/meshes/Gofa/gofa_base_link.STL" />
            </geometry>
            <material name="gofa_color" />
        </visual>
        <collision>
            <origin rpy="0 0 0" xyz="0 0 0" />
            <geometry>
                <mesh filename="package://omnicore_description/meshes/Gofa/gofa_base_link.STL" />
            </geometry>
        </collision>
    </link>
    <!-- Link 1 -->
    <link name="L1">
        <inertial>
            <origin rpy="0 0 0" xyz="2.08682453325091E-06 0.0103608399967513 0.0705307203199506" />
            <mass value="2.76743491139404" />
            <inertia ixx="0.0115158625894577" ixy="6.37197693598838E-08" ixz="5.98954393680154E-09" iyy="0.006494848329231" iyz="-0.000196668400316843" izz="0.0109446835358581" />
        </inertial>
        <visual>
            <origin rpy="0 0 0" xyz="0 0 0" />
            <geometry>
                <mesh filename="package://omnicore_description/meshes/Gofa/L1.STL" />
            </geometry>
            <material name="gofa_color" />
        </visual>
        <collision>
            <origin rpy="0 0 0" xyz="0 0 0" />
            <geometry>
                <mesh filename="package://omnicore_description/meshes/Gofa/L1.STL" />
            </geometry>
        </collision>
    </link>
    <joint name="J1" type="revolute">
        <origin rpy="0 0 0" xyz="0 0 0.1875" />
        <parent link="gofa_base_link" />
        <child link="L1" />
        <axis xyz="0 0 1" />
        <limit effort="300" lower="-3.141592653589793" upper="3.141592653589793" velocity="2.181661564992912" />
        <dynamics damping="0.5" />
    </joint>
    <!-- Link2 -->
    <link name="L2">
        <inertial>
            <origin rpy="0 0 0" xyz="1.34018352211628E-06 -0.0500118376116071 0.222001399322246" />
            <mass value="4.28904168670464" />
            <inertia ixx="0.130524729873898" ixy="1.31811857134115E-07" ixz="1.99022457670482E-06" iyy="0.133278449324229" iyz="-4.48622200366709E-07" izz="0.00669457974697178" />
        </inertial>
        <visual>
            <origin rpy="0 0 0" xyz="0 0 0" />
            <geometry>
                <mesh filename="package://omnicore_description/meshes/Gofa/L2.STL" />
            </geometry>
            <material name="gofa_color" />
        </visual>
        <collision>
            <origin rpy="0 0 0" xyz="0 0 0" />
            <geometry>
                <mesh filename="package://omnicore_description/meshes/Gofa/L2.STL" />
            </geometry>
        </collision>
    </link>
    <joint name="J2" type="revolute">
        <origin rpy="0 0 0" xyz="0 -0.085 0.0775" />
        <parent link="L1" />
        <child link="L2" />
        <axis xyz="0 1 0" />
        <limit effort="300" lower="-3.141592653589793" upper="3.141592653589793" velocity="2.181661564992912" />
        <dynamics damping="0.5" />
    </joint>
    <!-- Link3 -->
    <link name="L3">
        <inertial>
            <origin rpy="0 0 0" xyz="0.0128129281453599 0.0944171780907046 0.0247427540642403" />
            <mass value="3.38333107992875" />
            <inertia ixx="0.0175626138728642" ixy="0.000364866179108744" ixz="-0.00318670290285352" iyy="0.0140230068919562" iyz="0.000704668055158407" izz="0.013275205067567" />
        </inertial>
        <visual>
            <origin rpy="0 0 0" xyz="0 0 0" />
            <geometry>
                <mesh filename="package://omnicore_description/meshes/Gofa/L3.STL" />
            </geometry>
            <material name="gofa_color" />
        </visual>
        <collision>
            <origin rpy="0 0 0" xyz="0 0 0" />
            <geometry>
                <mesh filename="package://omnicore_description/meshes/Gofa/L3.STL" />
            </geometry>
        </collision>
    </link>
    <joint name="J3" type="revolute">
        <origin rpy="0 0 0" xyz="0 -0.00100000000000007 0.444" />
        <parent link="L2" />
        <child link="L3" />
        <axis xyz="0 1 0" />
        <limit effort="300" lower="-3.9269908169872414" upper="1.4835298641951802" velocity="2.443460952792061" />
        <dynamics damping="0.5" />
    </joint>
    <!-- Link4 -->
    <link name="L4">
        <inertial>
            <origin rpy="0 0 0" xyz="0.160558561602322 0.041976811408979 -2.36623354021859E-07" />
            <mass value="2.77857535641324" />
            <inertia ixx="0.00881683095901354" ixy="-0.010746260580237" ixz="1.2899930119841E-07" iyy="0.0340754175571832" iyz="3.96362791626429E-08" izz="0.0389358932156922" />
        </inertial>
        <visual>
            <origin rpy="0 0 0" xyz="0 0 0" />
            <geometry>
                <mesh filename="package://omnicore_description/meshes/Gofa/L4.STL" />
            </geometry>
            <material name="gofa_color" />
        </visual>
        <collision>
            <origin rpy="0 0 0" xyz="0 0 0" />
            <geometry>
                <mesh filename="package://omnicore_description/meshes/Gofa/L4.STL" />
            </geometry>
        </collision>
    </link>
    <joint name="J4" type="revolute">
        <origin rpy="0 0 0" xyz="0.096 0.0860000000000001 0.11" />
        <parent link="L3" />
        <child link="L4" />
        <axis xyz="1 0 0" />
        <limit effort="300" lower="-3.141592653589793" upper="3.141592653589793" velocity="3.490658503988659" />
        <dynamics damping="0.5" />
    </joint>
    <!-- Link5 -->
    <link name="L5">
        <inertial>
            <origin rpy="0 0 0" xyz="-0.0147152361879962 -0.0785646469392633 0.0427558021601431" />
            <mass value="3.01105814739001" />
            <inertia ixx="0.0114597336686444" ixy="0.000180094704361231" ixz="0.00165207280226761" iyy="0.013561904467501" iyz="-0.000525272443978826" izz="0.0108480119549914" />
        </inertial>
        <visual>
            <origin rpy="0 0 0" xyz="0 0 0" />
            <geometry>
                <mesh filename="package://omnicore_description/meshes/Gofa/L5.STL" />
            </geometry>
            <material name="gofa_color" />
        </visual>
        <collision>
            <origin rpy="0 0 0" xyz="0 0 0" />
            <geometry>
                <mesh filename="package://omnicore_description/meshes/Gofa/L5.STL" />
            </geometry>
        </collision>
    </link>
    <joint name="J5" type="revolute">
        <origin rpy="0 0 0" xyz="0.374 0.0744999999999998 0" />
        <parent link="L4" />
        <child link="L5" />
        <axis xyz="0 1 0" />
        <limit effort="300" lower="-3.141592653589793" upper="3.141592653589793" velocity="3.490658503988659" />
        <dynamics damping="0.5" />
    </joint>
    <!-- Link6 -->
    <link name="L6">
        <inertial>
            <origin rpy="0 0 0" xyz="0.0137506852604966 0.000239804131398652 -0.000341962798940165" />
            <mass value="0.146500988015653" />
            <inertia ixx="0.000128977630055306" ixy="-8.7622752508613E-08" ixz="1.18851551870012E-07" iyy="7.61118177829087E-05" iyz="-6.49821554399679E-07" izz="7.65022909768016E-05" />
        </inertial>
        <visual>
            <origin rpy="0 0 0" xyz="0 0 0" />
            <geometry>
                <mesh filename="package://omnicore_description/meshes/Gofa/L6.STL" />
            </geometry>
            <material name="gofa_color" />
        </visual>
        <collision>
            <origin rpy="0 0 0" xyz="0 0 0" />
            <geometry>
                <mesh filename="package://omnicore_description/meshes/Gofa/L6.STL" />
            </geometry>
        </collision>
    </link>
    <joint name="J6" type="revolute">
        <origin rpy="0 0 0" xyz="0.0679999999999995 -0.0744999999999998 0.0800000000000003" />
        <parent link="L5" />
        <child link="L6" />
        <axis xyz="1 0 0" />
        <limit effort="300" lower="-4.71238898038469" upper="4.71238898038469" velocity="3.490658503988659" />
        <dynamics damping="0.5" />
    </joint>
    <!-- Flange -->
    <link name="flange" />
    <joint name="L6_to_flange" type="fixed">
        <origin rpy="0 1.5707963267948966 0" xyz="0.033599981 0 0" />
        <parent link="L6" />
        <child link="flange" />
    </joint>
    <transmission name="gofa_tran_1">
        <type>transmission_interface/SimpleTransmission</type>
        <joint name="J1">
            <hardwareInterface>hardware_interface/PositionJointInterface</hardwareInterface>
        </joint>
        <actuator name="gofa_motor_1">
            <hardwareInterface>hardware_interface/PositionJointInterface</hardwareInterface>
            <mechanicalReduction>1</mechanicalReduction>
        </actuator>
    </transmission>
    <transmission name="gofa_tran_2">
        <type>transmission_interface/SimpleTransmission</type>
        <joint name="J2">
            <hardwareInterface>hardware_interface/PositionJointInterface</hardwareInterface>
        </joint>
        <actuator name="gofa_motor_2">
            <hardwareInterface>hardware_interface/PositionJointInterface</hardwareInterface>
            <mechanicalReduction>1</mechanicalReduction>
        </actuator>
    </transmission>
    <transmission name="gofa_tran_3">
        <type>transmission_interface/SimpleTransmission</type>
        <joint name="J3">
            <hardwareInterface>hardware_interface/PositionJointInterface</hardwareInterface>
        </joint>
        <actuator name="gofa_motor_3">
            <hardwareInterface>hardware_interface/PositionJointInterface</hardwareInterface>
            <mechanicalReduction>1</mechanicalReduction>
        </actuator>
    </transmission>
    <transmission name="gofa_tran_4">
        <type>transmission_interface/SimpleTransmission</type>
        <joint name="J4">
            <hardwareInterface>hardware_interface/PositionJointInterface</hardwareInterface>
        </joint>
        <actuator name="gofa_motor_4">
            <hardwareInterface>hardware_interface/PositionJointInterface</hardwareInterface>
            <mechanicalReduction>1</mechanicalReduction>
        </actuator>
    </transmission>
    <transmission name="gofa_tran_5">
        <type>transmission_interface/SimpleTransmission</type>
        <joint name="J5">
            <hardwareInterface>hardware_interface/PositionJointInterface</hardwareInterface>
        </joint>
        <actuator name="gofa_motor_5">
            <hardwareInterface>hardware_interface/PositionJointInterface</hardwareInterface>
            <mechanicalReduction>1</mechanicalReduction>
        </actuator>
    </transmission>
    <transmission name="gofa_tran_6">
        <type>transmission_interface/SimpleTransmission</type>
        <joint name="J6">
            <hardwareInterface>hardware_interface/PositionJointInterface</hardwareInterface>
        </joint>
        <actuator name="gofa_motor_6">
            <hardwareInterface>hardware_interface/PositionJointInterface</hardwareInterface>
            <mechanicalReduction>1</mechanicalReduction>
        </actuator>
    </transmission>
    <!-- Launching each component -->
    <!-- Gripper's main body -->
    <!-- Define a material -->
    <!-- <material name="Black">
    <color rgba="0.1 0.1 0.1 1" />
  </material> -->
    <!-- <material name="Grey">
    <color rgba="0.5 0.5 0.5 1" />
  </material> -->
    <!-- Define a material -->
    <material name="finger_black">
        <color rgba="0.1 0.1 0.1 1" />
    </material>
    <!-- Main gripper body -->
    <link name="gripper_body">
        <visual>
            <origin rpy="0 0 0" xyz="0 0 0" />
            <geometry>
                <mesh filename="package://schunk_description/meshes/egk40/visual/egk40_body.dae" scale="0.001 0.001 0.001" />
            </geometry>
            <material name="Grey" />
        </visual>
        <collision>
            <origin rpy="0 0 0" xyz="0 0 0" />
            <geometry>
                <mesh filename="package://schunk_description/meshes/egk40/collision/egk40_body.stl" scale="0.001 0.001 0.001" />
            </geometry>
        </collision>
        <inertial>
            <origin rpy="0 0 0" xyz="0 0 0" />
            <mass value="1.5" />
            <inertia ixx="1.0" ixy="0.0" ixz="0.0" iyy="1.0" iyz="0.0" izz="1.0" />
        </inertial>
    </link>
    <!-- Finger 1 -->
    <link name="finger1">
        <visual>
            <origin rpy="0 0 0" xyz="0 0 0" />
            <geometry>
                <mesh filename="package://schunk_description/meshes/egk40/visual/slider.dae" scale="0.001 0.001 0.001" />
            </geometry>
            <material name="Black" />
        </visual>
        <collision>
            <origin rpy="0 0 0" xyz="0 0 0" />
            <geometry>
                <mesh filename="package://schunk_description/meshes/egk40/collision/slider.stl" scale="0.001 0.001 0.001" />
            </geometry>
        </collision>
        <inertial>
            <origin rpy="0 0 0" xyz="0 0 0" />
            <mass value="0.3" />
            <inertia ixx="0.1" ixy="0.0" ixz="0.0" iyy="0.1" iyz="0.0" izz="0.1" />
        </inertial>
    </link>
    <!-- Finger 2 -->
    <link name="finger2">
        <visual>
            <origin rpy="0 0 0" xyz="0 0 0" />
            <geometry>
                <mesh filename="package://schunk_description/meshes/egk40/visual/slider.dae" scale="0.001 0.001 0.001" />
            </geometry>
            <material name="Black" />
        </visual>
        <collision>
            <origin rpy="0 0 0" xyz="0 0 0" />
            <geometry>
                <mesh filename="package://schunk_description/meshes/egk40/collision/slider.stl" scale="0.001 0.001 0.001" />
            </geometry>
        </collision>
        <inertial>
            <origin rpy="0 0 0" xyz="0 0 0" />
            <mass value="0.3" />
            <inertia ixx="0.1" ixy="0.0" ixz="0.0" iyy="0.1" iyz="0.0" izz="0.1" />
        </inertial>
    </link>
    <!-- joints: main serial chain -->
    <joint name="finger1_joint" type="prismatic">
        <parent link="gripper_body" />
        <child link="finger1" />
        <origin rpy="0 1.5707963267948966 0" xyz="0.016 0.071 0.02" />
        <limit effort="1000.0" lower="0.0" upper="0.0415" velocity="10.0" />
    </joint>
    <joint name="finger2_joint" type="prismatic">
        <parent link="gripper_body" />
        <child link="finger2" />
        <origin rpy="0 -1.5707963267948966 0" xyz="-0.016 0.071 -0.02" />
        <limit effort="1000.0" lower="0.0" upper="0.0415" velocity="10.0" />
    </joint>
    <!-- Finger link -->
    <link name="leftfinger_body">
        <visual>
            <origin rpy="0 0 0" xyz="0 0 0" />
            <geometry>
                <mesh filename="package://schunk_description/meshes/fingers/visual/flat_finger.dae" scale="0.001 0.001 0.001" />
            </geometry>
            <material name="finger_black" />
        </visual>
        <collision>
            <origin rpy="0 0 0" xyz="0 0 0" />
            <geometry>
                <mesh filename="package://schunk_description/meshes/fingers/collision/flat_finger_raw.stl" scale="0.001 0.001 0.001" />
            </geometry>
        </collision>
        <inertial>
            <origin rpy="0 0 0" xyz="0 0 0" />
            <mass value="0.1" />
            <inertia ixx="0.001" ixy="0.0" ixz="0.0" iyy="0.001" iyz="0.0" izz="0.001" />
        </inertial>
    </link>
    <!-- joints: main serial chain -->
    <joint name="leftfinger_joint" type="fixed">
        <parent link="finger1" />
        <child link="leftfinger_body" />
        <origin rpy="0 0 0" xyz="0.0 0.012 0.0" />
    </joint>
    <gazebo reference="leftfinger_joint">
        <disableFixedJointLumping>true</disableFixedJointLumping>
        <preserveFixedJoint>true</preserveFixedJoint>
    </gazebo>
    <!-- Finger link -->
    <link name="rightfinger_body">
        <visual>
            <origin rpy="0 0 0" xyz="0 0 0" />
            <geometry>
                <mesh filename="package://schunk_description/meshes/fingers/visual/flat_finger.dae" scale="0.001 0.001 0.001" />
            </geometry>
            <material name="finger_black" />
        </visual>
        <collision>
            <origin rpy="0 0 0" xyz="0 0 0" />
            <geometry>
                <mesh filename="package://schunk_description/meshes/fingers/collision/flat_finger_raw.stl" scale="0.001 0.001 0.001" />
            </geometry>
        </collision>
        <inertial>
            <origin rpy="0 0 0" xyz="0 0 0" />
            <mass value="0.1" />
            <inertia ixx="0.001" ixy="0.0" ixz="0.0" iyy="0.001" iyz="0.0" izz="0.001" />
        </inertial>
    </link>
    <!-- joints: main serial chain -->
    <joint name="rightfinger_joint" type="fixed">
        <parent link="finger2" />
        <child link="rightfinger_body" />
        <origin rpy="0 0 0" xyz="0.0 0.012 0.0" />
    </joint>
    <gazebo reference="rightfinger_joint">
        <disableFixedJointLumping>true</disableFixedJointLumping>
        <preserveFixedJoint>true</preserveFixedJoint>
    </gazebo>
    <!-- Joint connecting gripper base (gripper_body) to parent -->
    <joint name="parent_to_gripper" type="fixed">
        <parent link="flange" />
        <child link="gripper_body" />
        <origin rpy="1.5707963267948966 0.0 0.0" xyz="0.0 0.0 0.011" />
    </joint>
    <!-- Add grasp link frame -->
    <!-- <joint name="gripper_body_to_grasp_joint" type="fixed">
      <parent link="${parent}" />
      <child  link="grasp_link" />
      <origin xyz="0.0 0.0 0.13" rpy="0.0 0.0 ${-pi}" />
    </joint>
    
    <link name="grasp_link" /> -->
    <!-- Trasmissions -->
    <transmission name="tran_1">
        <type>transmission_interface/SimpleTransmission</type>
        <joint name="finger1_joint">
            <hardwareInterface>hardware_interface/EffortJointInterface</hardwareInterface>
        </joint>
        <actuator name="motor_1">
            <hardwareInterface>hardware_interface/EffortJointInterface</hardwareInterface>
            <mechanicalReduction>1</mechanicalReduction>
        </actuator>
    </transmission>
    <transmission name="tran_2">
        <type>transmission_interface/SimpleTransmission</type>
        <joint name="finger2_joint">
            <hardwareInterface>hardware_interface/EffortJointInterface</hardwareInterface>
        </joint>
        <actuator name="motor_2">
            <hardwareInterface>hardware_interface/EffortJointInterface</hardwareInterface>
            <mechanicalReduction>1</mechanicalReduction>
        </actuator>
    </transmission>
    <gazebo>
        <!-- <plugin name="ros_control" filename="libgazebo_ros_control.so">
        </plugin> -->
        <!-- It is loaded in the robot_arm.urdf.xacro -->
    </gazebo>
    <!-- Disabling gravity -->
    <gazebo reference="finger1">
        <gravity>0</gravity>
    </gazebo>
    <gazebo reference="finger2">
        <gravity>0</gravity>
    </gazebo>
    <gazebo>
        <plugin filename="libgazebo_grasp_fix.so" name="gazebo_grasp_fix">
            <arm>
                <arm_name>gofa</arm_name>
                <palm_link>finger1</palm_link>
                <gripper_link>leftfinger_body</gripper_link>
                <palm_link>finger2</palm_link>
                <gripper_link>rightfinger_body</gripper_link>
            </arm>
            <forces_angle_tolerance>100</forces_angle_tolerance>
            <update_rate>4</update_rate>
            <grip_count_threshold>4</grip_count_threshold>
            <max_grip_count>8</max_grip_count>
            <release_tolerance>0.005</release_tolerance>
            <disable_collisions_on_attach>false</disable_collisions_on_attach>
            <contact_topic>__default_topic__</contact_topic>
        </plugin>
    </gazebo>
    <gazebo>
        <plugin filename="libgazebo_ros_control.so" name="ros_control" />
    </gazebo>
</robot>
