<?xml version="1.0" ?>
<!-- =================================================================================== -->
<!-- |    This document was autogenerated by xacro from /home/niccolo/tmp/src/ABB_omnicore_ros_driver/robots_description/xacro/robot.urdf.xacro | -->
<!-- |    EDITING THIS FILE BY HAND IS NOT RECOMMENDED                                 | -->
<!-- =================================================================================== -->
<robot name="robot">
    <!-- Parameters -->
    <arg default="gofa" name="name" />
    <!-- World fixed joint -->
    <link name="world" />
    <!-- Robot -->
    <material name="Black">
        <color rgba="0.0 0.0 0.0 1.0" />
    </material>
    <material name="Blue">
        <color rgba="0.0 0.0 0.8 1.0" />
    </material>
    <material name="Green">
        <color rgba="0.0 0.8 0.0 1.0" />
    </material>
    <material name="Grey">
        <color rgba="0.5 0.5 0.5 1.0" />
    </material>
    <material name="Light_Grey">
        <color rgba="0.8 0.8 0.8 1.0" />
    </material>
    <material name="Ivory">
        <color rgba="1.0 1.0 0.94 1.0" />
    </material>
    <material name="Orange">
        <color rgba="1.0 0.4235294117647059 0.0392156862745098 1.0" />
    </material>
    <material name="Brown">
        <color rgba="0.8705882352941177 0.8117647058823529 0.7647058823529411 1.0" />
    </material>
    <material name="Red">
        <color rgba="0.8 0.0 0.0 1.0" />
    </material>
    <material name="White">
        <color rgba="1.0 1.0 1.0 1.0" />
    </material>
    <!--Import
        the yumi servo gripper macro -->
    <!-- <xacro:include filename="$(find robots_description)/Grippers/YumiServoGripper/yumi_servo_gripper.xacro" /> -->
    <!-- joint between external and base -->
    <joint name="joint_0" type="fixed">
        <origin rpy="0 0 0" xyz="0 0 0" />
        <parent link="world" />
        <child link="single_yumi_base_link" />
    </joint>
    <link name="single_yumi_base_link">
        <visual>
            <origin rpy="0 0 0" xyz="0 0 0" />
            <geometry>
                <mesh filename="package://robots_description/meshes/Yumi/single_arm_base.stl" />
            </geometry>
            <material name="Grey" />
        </visual>
        <!-- <collision>
        <origin xyz="0 0 0" rpy="0 0 0" />
        <geometry>
          <mesh filename="package://robots_description/meshes/Yumi/single_arm_base.stl" />
        </geometry>
        <material name="Grey" />
      </collision> -->
        <inertial>
            <origin rpy="0 0 0" xyz="0 0 0" />
            <mass value="0.1" />
            <inertia ixx="0.1" ixy="0" ixz="0" iyy="0.1" iyz="0" izz="0.1" />
        </inertial>
    </link>
    <!-- joint between body and link_1 -->
    <joint name="joint_1" type="revolute">
        <parent link="single_yumi_base_link" />
        <child link="link_1" />
        <origin rpy="0.0 0.0 3.141592653589793" xyz="0.0 0.0 0.2048" />
        <axis xyz="0 0 1" />
        <limit effort="300" lower="-2.940879789610445" upper="2.940879789610445" velocity="3.141592653589793" />
        <dynamics damping="0.5" />
    </joint>
    <link name="link_1">
        <inertial>
            <origin rpy="0 0 0" xyz="0 -0.03 0.12" />
            <mass value="2" />
            <inertia ixx="0.1" ixy="0" ixz="0" iyy="0.1" iyz="0" izz="0.1" />
        </inertial>
        <visual>
            <origin rpy="0 0 0" xyz="0 0 0" />
            <geometry>
                <mesh filename="package://robots_description/meshes/Yumi/link_1.stl" />
            </geometry>
            <material name="Grey" />
        </visual>
        <collision>
            <origin rpy="0 0 0" xyz="0 0 0" />
            <geometry>
                <mesh filename="package://robots_description/meshes/Yumi/coarse/link_1.stl" />
            </geometry>
            <material name="Grey" />
        </collision>
    </link>
    <!-- joint between link_1 and link_2 -->
    <joint name="joint_2" type="revolute">
        <parent link="link_1" />
        <child link="link_2" />
        <origin rpy="1.5707963267948966 0.0 0.0" xyz="0.03 0.0 0.1" />
        <axis xyz="0 0 1" />
        <limit effort="300" lower="-2.504547476611863" upper="0.7592182246175333" velocity="3.141592653589793" />
        <dynamics damping="0.5" />
    </joint>
    <link name="link_2">
        <inertial>
            <origin rpy="0 0 0" xyz="0 0 0" />
            <mass value="2" />
            <inertia ixx="0.1" ixy="0" ixz="0" iyy="0.1" iyz="0" izz="0.1" />
        </inertial>
        <visual>
            <origin rpy="0 0 0" xyz="0 0 0" />
            <geometry>
                <mesh filename="package://robots_description/meshes/Yumi/link_2.stl" />
            </geometry>
            <material name="Grey" />
        </visual>
        <collision>
            <origin rpy="0 0 0" xyz="0 0 0" />
            <geometry>
                <mesh filename="package://robots_description/meshes/Yumi/coarse/link_2.stl" />
            </geometry>
            <material name="Grey" />
        </collision>
    </link>
    <!-- joint between link_2 and link_3 -->
    <joint name="joint_3" type="revolute">
        <parent link="link_2" />
        <child link="link_3" />
        <origin rpy="-1.5707963267948966 0.0 0.0" xyz="-0.03 0.17283 0.0" />
        <axis xyz="0 0 1" />
        <limit effort="300" lower="-2.940879789610445" upper="2.940879789610445" velocity="3.141592653589793" />
        <dynamics damping="0.5" />
    </joint>
    <link name="link_3">
        <inertial>
            <origin rpy="0 0 0" xyz="0 0 0" />
            <mass value="2" />
            <inertia ixx="0.1" ixy="0" ixz="0" iyy="0.1" iyz="0" izz="0.1" />
        </inertial>
        <visual>
            <origin rpy="0 0 0" xyz="0 0 0" />
            <geometry>
                <mesh filename="package://robots_description/meshes/Yumi/link_3.stl" />
            </geometry>
            <material name="Grey" />
        </visual>
        <collision>
            <origin rpy="0 0 0" xyz="0 0 0" />
            <geometry>
                <mesh filename="package://robots_description/meshes/Yumi/coarse/link_3.stl" />
            </geometry>
            <material name="Grey" />
        </collision>
    </link>
    <!-- joint between link_3 and link_4 -->
    <joint name="joint_4" type="revolute">
        <parent link="link_3" />
        <child link="link_4" />
        <origin rpy="1.5707963267948966 -1.5707963267948966 0.0" xyz="-0.04188 0.0 0.07873" />
        <axis xyz="0 0 1" />
        <limit effort="300" lower="-2.155481626212997" upper="1.3962634015954636" velocity="3.141592653589793" />
        <dynamics damping="0.5" />
    </joint>
    <link name="link_4">
        <inertial>
            <origin rpy="0 0 0" xyz="0 0 0" />
            <mass value="2" />
            <inertia ixx="0.1" ixy="0" ixz="0" iyy="0.1" iyz="0" izz="0.1" />
        </inertial>
        <visual>
            <origin rpy="0 0 0" xyz="0 0 0" />
            <geometry>
                <mesh filename="package://robots_description/meshes/Yumi/link_4.stl" />
            </geometry>
            <material name="Grey" />
        </visual>
        <collision>
            <origin rpy="0 0 0" xyz="0 0 0" />
            <geometry>
                <mesh filename="package://robots_description/meshes/Yumi/coarse/link_4.stl" />
            </geometry>
            <material name="Grey" />
        </collision>
    </link>
    <!-- joint between link_4 and link_5 -->
    <joint name="joint_5" type="revolute">
        <parent link="link_4" />
        <child link="link_5" />
        <origin rpy="-1.5707963267948966 0.0 0.0" xyz="0.0405 0.16461 0.0" />
        <axis xyz="0 0 1" />
        <limit effort="300" lower="-5.061454830783555" upper="5.061454830783555" velocity="6.981317007977318" />
        <dynamics damping="0.5" />
    </joint>
    <link name="link_5">
        <inertial>
            <origin rpy="0 0 0" xyz="0 0 0" />
            <mass value="2" />
            <inertia ixx="0.1" ixy="0" ixz="0" iyy="0.1" iyz="0" izz="0.1" />
        </inertial>
        <visual>
            <origin rpy="0 0 0" xyz="0 0 0" />
            <geometry>
                <mesh filename="package://robots_description/meshes/Yumi/link_5.stl" />
            </geometry>
            <material name="Grey" />
        </visual>
        <collision>
            <origin rpy="0 0 0" xyz="0 0 0" />
            <geometry>
                <mesh filename="package://robots_description/meshes/Yumi/coarse/link_5.stl" />
            </geometry>
            <material name="Grey" />
        </collision>
    </link>
    <!-- joint between link_5 and link_6 -->
    <joint name="joint_6" type="revolute">
        <parent link="link_5" />
        <child link="link_6" />
        <origin rpy="1.5707963267948966 0.0 0.0" xyz="-0.027 0 0.10039" />
        <axis xyz="0 0 1" />
        <limit effort="300" lower="-1.53588974175501" upper="2.4085543677521746" velocity="6.981317007977318" />
        <dynamics damping="0.5" />
    </joint>
    <link name="link_6">
        <inertial>
            <origin rpy="0 0 0" xyz="0 0 0" />
            <mass value="2" />
            <inertia ixx="0.1" ixy="0" ixz="0" iyy="0.1" iyz="0" izz="0.1" />
        </inertial>
        <visual>
            <origin rpy="0 0 0" xyz="0 0 0" />
            <geometry>
                <mesh filename="package://robots_description/meshes/Yumi/link_6.stl" />
            </geometry>
            <material name="Grey" />
        </visual>
        <collision>
            <origin rpy="0 0 0" xyz="0 0 0" />
            <geometry>
                <mesh filename="package://robots_description/meshes/Yumi/coarse/link_6.stl" />
            </geometry>
            <material name="Grey" />
        </collision>
    </link>
    <!-- joint between link_6 and link_7 -->
    <joint name="joint_7" type="revolute">
        <parent link="link_6" />
        <child link="link_7" />
        <origin rpy="-1.5707963267948966 0.0 0.0" xyz="0.027 0.029 0.0" />
        <axis xyz="0 0 1" />
        <limit effort="300" lower="-3.9968039870670142" upper="3.9968039870670142" velocity="6.981317007977318" />
        <dynamics damping="0.5" />
    </joint>
    <link name="link_7">
        <inertial>
            <origin rpy="0 0 0" xyz="0 0 0" />
            <mass value="2" />
            <inertia ixx="0.1" ixy="0" ixz="0" iyy="0.1" iyz="0" izz="0.1" />
        </inertial>
        <visual>
            <origin rpy="0 0 0" xyz="0 0 0" />
            <geometry>
                <mesh filename="package://robots_description/meshes/Yumi/link_7.stl" />
            </geometry>
            <material name="Grey" />
        </visual>
        <collision>
            <origin rpy="0 0 0" xyz="0 0 0" />
            <geometry>
                <mesh filename="package://robots_description/meshes/Yumi/coarse/link_7.stl" />
            </geometry>
            <material name="Grey" />
        </collision>
    </link>
    <transmission name="single_arm_tran_1">
        <type>transmission_interface/SimpleTransmission</type>
        <joint name="joint_1">
            <hardwareInterface>PositionJointInterface</hardwareInterface>
        </joint>
        <actuator name="single_arm_motor_1">
            <hardwareInterface>PositionJointInterface</hardwareInterface>
            <mechanicalReduction>1</mechanicalReduction>
        </actuator>
    </transmission>
    <transmission name="single_arm_tran_2">
        <type>transmission_interface/SimpleTransmission</type>
        <joint name="joint_2">
            <hardwareInterface>PositionJointInterface</hardwareInterface>
        </joint>
        <actuator name="single_arm_motor_2">
            <hardwareInterface>PositionJointInterface</hardwareInterface>
            <mechanicalReduction>1</mechanicalReduction>
        </actuator>
    </transmission>
    <transmission name="single_arm_tran_3">
        <type>transmission_interface/SimpleTransmission</type>
        <joint name="joint_3">
            <hardwareInterface>PositionJointInterface</hardwareInterface>
        </joint>
        <actuator name="single_arm_motor_3">
            <hardwareInterface>PositionJointInterface</hardwareInterface>
            <mechanicalReduction>1</mechanicalReduction>
        </actuator>
    </transmission>
    <transmission name="single_arm_tran_4">
        <type>transmission_interface/SimpleTransmission</type>
        <joint name="joint_4">
            <hardwareInterface>PositionJointInterface</hardwareInterface>
        </joint>
        <actuator name="single_arm_motor_4">
            <hardwareInterface>PositionJointInterface</hardwareInterface>
            <mechanicalReduction>1</mechanicalReduction>
        </actuator>
    </transmission>
    <transmission name="single_arm_tran_5">
        <type>transmission_interface/SimpleTransmission</type>
        <joint name="joint_5">
            <hardwareInterface>PositionJointInterface</hardwareInterface>
        </joint>
        <actuator name="single_arm_motor_5">
            <hardwareInterface>PositionJointInterface</hardwareInterface>
            <mechanicalReduction>1</mechanicalReduction>
        </actuator>
    </transmission>
    <transmission name="single_arm_tran_6">
        <type>transmission_interface/SimpleTransmission</type>
        <joint name="joint_6">
            <hardwareInterface>PositionJointInterface</hardwareInterface>
        </joint>
        <actuator name="single_arm_motor_6">
            <hardwareInterface>PositionJointInterface</hardwareInterface>
            <mechanicalReduction>1</mechanicalReduction>
        </actuator>
    </transmission>
    <transmission name="single_arm_tran_7">
        <type>transmission_interface/SimpleTransmission</type>
        <joint name="joint_7">
            <hardwareInterface>PositionJointInterface</hardwareInterface>
        </joint>
        <actuator name="single_arm_motor_7">
            <hardwareInterface>PositionJointInterface</hardwareInterface>
            <mechanicalReduction>1</mechanicalReduction>
        </actuator>
    </transmission>
    <!-- Gripper -->
    <!-- <xacro:yumi_servo_gripper name="gripper" parent="link_7" hardware_interface="${gripper_interface}">
            <origin xyz="0 0 0.007" rpy="0 0 ${PI}" />
        </xacro:yumi_servo_gripper> -->
    <gazebo>
        <plugin name="gazebo_ros_control">
            <robotNamespace>/</robotNamespace>
        </plugin>
    </gazebo>
</robot>

