<?xml version="1.0" ?>
<!-- =================================================================================== -->
<!-- |    This document was autogenerated by xacro from /home/niccolo/PhD/Robots/ABB/Gofa/ROS/src/abb_wrapper/robots_description/xacro/robot.urdf.xacro | -->
<!-- |    EDITING THIS FILE BY HAND IS NOT RECOMMENDED                                 | -->
<!-- =================================================================================== -->
<robot name="robot">
    <!-- Parameters -->
    <arg default="gofa" name="name" />
    <!-- World fixed joint -->
    <link name="world" />
    <!-- Robot -->
    <!-- GoFa color -->
    <material name="gofa_color">
        <color rgba="0.792156862745098 0.819607843137255 0.933333333333333 1" />
    </material>
    <joint name="world_to_base" type="fixed">
        <origin rpy="0 0 0" xyz="0 0 0" />
        <parent link="world" />
        <child link="base" />
    </joint>
    <link name="base">
        <inertial>
            <origin rpy="0 0 0" xyz="-0.0012013793465437 -0.000175191786981708 0.0862146007385352" />
            <mass value="3.50083457958494" />
            <inertia ixx="0.0153015257917955" ixy="-6.40155032892694E-05" ixz="-0.000276708687772683" iyy="0.0159333503953857" iyz="-3.98029144780725E-05" izz="0.0112162302268266" />
        </inertial>
        <visual>
            <origin rpy="0 0 0" xyz="0 0 0" />
            <geometry>
                <mesh filename="package://robots_description/meshes/Gofa/base.STL" />
            </geometry>
            <material name="gofa_color" />
        </visual>
        <collision>
            <origin rpy="0 0 0" xyz="0 0 0" />
            <geometry>
                <mesh filename="package://robots_description/meshes/Gofa/base.STL" />
            </geometry>
        </collision>
    </link>
    <link name="L1">
        <inertial>
            <origin rpy="0 0 0" xyz="2.08682453325091E-06 0.0103608399967513 0.0705307203199506" />
            <mass value="2.76743491139404" />
            <inertia ixx="0.0115158625894577" ixy="6.37197693598838E-08" ixz="5.98954393680154E-09" iyy="0.006494848329231" iyz="-0.000196668400316843" izz="0.0109446835358581" />
        </inertial>
        <visual>
            <origin rpy="0 0 0" xyz="0 0 0" />
            <geometry>
                <mesh filename="package://robots_description/meshes/Gofa/L1.STL" />
            </geometry>
            <material name="gofa_color" />
        </visual>
        <collision>
            <origin rpy="0 0 0" xyz="0 0 0" />
            <geometry>
                <mesh filename="package://robots_description/meshes/Gofa/L1.STL" />
            </geometry>
        </collision>
    </link>
    <joint name="J1" type="revolute">
        <origin rpy="0 0 0" xyz="0 0 0.1875" />
        <parent link="base" />
        <child link="L1" />
        <axis xyz="0 0 1" />
        <limit effort="0" lower="-3.141592653589793" upper="3.141592653589793" velocity="2.181661564992912" />
    </joint>
    <link name="L2">
        <inertial>
            <origin rpy="0 0 0" xyz="1.34018352211628E-06 -0.0500118376116071 0.222001399322246" />
            <mass value="4.28904168670464" />
            <inertia ixx="0.130524729873898" ixy="1.31811857134115E-07" ixz="1.99022457670482E-06" iyy="0.133278449324229" iyz="-4.48622200366709E-07" izz="0.00669457974697178" />
        </inertial>
        <visual>
            <origin rpy="0 0 0" xyz="0 0 0" />
            <geometry>
                <mesh filename="package://robots_description/meshes/Gofa/L2.STL" />
            </geometry>
            <material name="gofa_color" />
        </visual>
        <collision>
            <origin rpy="0 0 0" xyz="0 0 0" />
            <geometry>
                <mesh filename="package://robots_description/meshes/Gofa/L2.STL" />
            </geometry>
        </collision>
    </link>
    <joint name="J2" type="revolute">
        <origin rpy="0 0 0" xyz="0 -0.085 0.0775" />
        <parent link="L1" />
        <child link="L2" />
        <axis xyz="0 1 0" />
        <limit effort="0" lower="-3.141592653589793" upper="3.141592653589793" velocity="2.181661564992912" />
    </joint>
    <link name="L3">
        <inertial>
            <origin rpy="0 0 0" xyz="0.0128129281453599 0.0944171780907046 0.0247427540642403" />
            <mass value="3.38333107992875" />
            <inertia ixx="0.0175626138728642" ixy="0.000364866179108744" ixz="-0.00318670290285352" iyy="0.0140230068919562" iyz="0.000704668055158407" izz="0.013275205067567" />
        </inertial>
        <visual>
            <origin rpy="0 0 0" xyz="0 0 0" />
            <geometry>
                <mesh filename="package://robots_description/meshes/Gofa/L3.STL" />
            </geometry>
            <material name="gofa_color" />
        </visual>
        <collision>
            <origin rpy="0 0 0" xyz="0 0 0" />
            <geometry>
                <mesh filename="package://robots_description/meshes/Gofa/L3.STL" />
            </geometry>
        </collision>
    </link>
    <joint name="J3" type="revolute">
        <origin rpy="0 0 0" xyz="0 -0.00100000000000007 0.444" />
        <parent link="L2" />
        <child link="L3" />
        <axis xyz="0 1 0" />
        <limit effort="0" lower="-3.9269908169872414" upper="1.4835298641951802" velocity="2.443460952792061" />
    </joint>
    <link name="L4">
        <inertial>
            <origin rpy="0 0 0" xyz="0.160558561602322 0.041976811408979 -2.36623354021859E-07" />
            <mass value="2.77857535641324" />
            <inertia ixx="0.00881683095901354" ixy="-0.010746260580237" ixz="1.2899930119841E-07" iyy="0.0340754175571832" iyz="3.96362791626429E-08" izz="0.0389358932156922" />
        </inertial>
        <visual>
            <origin rpy="0 0 0" xyz="0 0 0" />
            <geometry>
                <mesh filename="package://robots_description/meshes/Gofa/L4.STL" />
            </geometry>
            <material name="gofa_color" />
        </visual>
        <collision>
            <origin rpy="0 0 0" xyz="0 0 0" />
            <geometry>
                <mesh filename="package://robots_description/meshes/Gofa/L4.STL" />
            </geometry>
        </collision>
    </link>
    <joint name="J4" type="revolute">
        <origin rpy="0 0 0" xyz="0.096 0.0860000000000001 0.11" />
        <parent link="L3" />
        <child link="L4" />
        <axis xyz="1 0 0" />
        <limit effort="0" lower="-3.141592653589793" upper="3.141592653589793" velocity="3.490658503988659" />
    </joint>
    <link name="L5">
        <inertial>
            <origin rpy="0 0 0" xyz="-0.0147152361879962 -0.0785646469392633 0.0427558021601431" />
            <mass value="3.01105814739001" />
            <inertia ixx="0.0114597336686444" ixy="0.000180094704361231" ixz="0.00165207280226761" iyy="0.013561904467501" iyz="-0.000525272443978826" izz="0.0108480119549914" />
        </inertial>
        <visual>
            <origin rpy="0 0 0" xyz="0 0 0" />
            <geometry>
                <mesh filename="package://robots_description/meshes/Gofa/L5.STL" />
            </geometry>
            <material name="gofa_color" />
        </visual>
        <collision>
            <origin rpy="0 0 0" xyz="0 0 0" />
            <geometry>
                <mesh filename="package://robots_description/meshes/Gofa/L5.STL" />
            </geometry>
        </collision>
    </link>
    <joint name="J5" type="revolute">
        <origin rpy="0 0 0" xyz="0.374 0.0744999999999998 0" />
        <parent link="L4" />
        <child link="L5" />
        <axis xyz="0 1 0" />
        <limit effort="0" lower="-3.141592653589793" upper="3.141592653589793" velocity="3.490658503988659" />
    </joint>
    <link name="L6">
        <inertial>
            <origin rpy="0 0 0" xyz="0.0137506852604966 0.000239804131398652 -0.000341962798940165" />
            <mass value="0.146500988015653" />
            <inertia ixx="0.000128977630055306" ixy="-8.7622752508613E-08" ixz="1.18851551870012E-07" iyy="7.61118177829087E-05" iyz="-6.49821554399679E-07" izz="7.65022909768016E-05" />
        </inertial>
        <visual>
            <origin rpy="0 0 0" xyz="0 0 0" />
            <geometry>
                <mesh filename="package://robots_description/meshes/Gofa/L6.STL" />
            </geometry>
            <material name="gofa_color" />
        </visual>
        <collision>
            <origin rpy="0 0 0" xyz="0 0 0" />
            <geometry>
                <mesh filename="package://robots_description/meshes/Gofa/L6.STL" />
            </geometry>
        </collision>
    </link>
    <joint name="J6" type="revolute">
        <origin rpy="0 0 0" xyz="0.0679999999999995 -0.0744999999999998 0.0800000000000003" />
        <parent link="L5" />
        <child link="L6" />
        <axis xyz="1 0 0" />
        <limit effort="0" lower="-3.141592653589793" upper="3.141592653589793" velocity="3.490658503988659" />
    </joint>
    <link name="flange" />
    <joint name="L6_to_flange" type="fixed">
        <origin rpy="0 1.5707963267948966 0" xyz="0.033599981 0 0" />
        <parent link="L6" />
        <child link="flange" />
    </joint>
    <!-- Gripper -->
    <transmission name="trans_J1">
        <type>transmission_interface/SimpleTransmission</type>
        <joint name="J1">
            <hardwareInterface>hardware_interface/PositionJointInterface</hardwareInterface>
        </joint>
        <actuator name="J1_motor">
            <hardwareInterface>hardware_interface/PositionJointInterface</hardwareInterface>
            <mechanicalReduction>1</mechanicalReduction>
        </actuator>
    </transmission>
    <transmission name="trans_J2">
        <type>transmission_interface/SimpleTransmission</type>
        <joint name="J2">
            <hardwareInterface>hardware_interface/PositionJointInterface</hardwareInterface>
        </joint>
        <actuator name="J2_motor">
            <hardwareInterface>hardware_interface/PositionJointInterface</hardwareInterface>
            <mechanicalReduction>1</mechanicalReduction>
        </actuator>
    </transmission>
    <transmission name="trans_J3">
        <type>transmission_interface/SimpleTransmission</type>
        <joint name="J3">
            <hardwareInterface>hardware_interface/PositionJointInterface</hardwareInterface>
        </joint>
        <actuator name="J3_motor">
            <hardwareInterface>hardware_interface/PositionJointInterface</hardwareInterface>
            <mechanicalReduction>1</mechanicalReduction>
        </actuator>
    </transmission>
    <transmission name="trans_J4">
        <type>transmission_interface/SimpleTransmission</type>
        <joint name="J4">
            <hardwareInterface>hardware_interface/PositionJointInterface</hardwareInterface>
        </joint>
        <actuator name="J4_motor">
            <hardwareInterface>hardware_interface/PositionJointInterface</hardwareInterface>
            <mechanicalReduction>1</mechanicalReduction>
        </actuator>
    </transmission>
    <transmission name="trans_J5">
        <type>transmission_interface/SimpleTransmission</type>
        <joint name="J5">
            <hardwareInterface>hardware_interface/PositionJointInterface</hardwareInterface>
        </joint>
        <actuator name="J5_motor">
            <hardwareInterface>hardware_interface/PositionJointInterface</hardwareInterface>
            <mechanicalReduction>1</mechanicalReduction>
        </actuator>
    </transmission>
    <transmission name="trans_J6">
        <type>transmission_interface/SimpleTransmission</type>
        <joint name="J6">
            <hardwareInterface>hardware_interface/PositionJointInterface</hardwareInterface>
        </joint>
        <actuator name="J6_motor">
            <hardwareInterface>hardware_interface/PositionJointInterface</hardwareInterface>
            <mechanicalReduction>1</mechanicalReduction>
        </actuator>
    </transmission>
    <gazebo>
        <plugin name="gazebo_ros_control">
            <robotNamespace>/</robotNamespace>
        </plugin>
    </gazebo>
</robot>

