<?xml version="1.0"?>
<robot name="yumi" xmlns:xacro="http://www.ros.org/wiki/xacro">
   
   <!-- Import Transmissions -->
   <xacro:include filename="$(find robots_description)/Grippers/YumiServoGripper/yumi_servo_gripper.transmission.xacro" />

   <!-- some constants -->
   <xacro:property name="joint_damping" value="0.5" />
   <xacro:property name="gripper_joint_damping" value="1.0" />
   <xacro:property name="max_gripper_effort" value="20" />
   <xacro:property name="max_gripper_velocity" value="2" />

   <xacro:macro name="yumi_servo_gripper" params="parent name hardware_interface fake_execution:=true *origin">

      <!--joint
      between {parent} and base-->
      <joint name="${parent}_joint" type="fixed">
         <origin xyz="0 0.0 0.0" rpy="0 0 0" />
         <parent link="${parent}" />
         <child link="${name}_base" />
      </joint>

      <link name="${name}_base">
         <inertial>
            <origin xyz="0 0 0" rpy="0 0 0" />
            <mass value="0.2" />
            <inertia ixx="0.0001" ixy="0" ixz="0" iyy="0.0001" iyz="0" izz="0.0001" />
         </inertial>
         <visual>
            <origin xyz="0 0 0" rpy="0 0 0" />
            <geometry>
               <mesh filename="package://robots_description/meshes/Yumi/gripper/base.stl" />
            </geometry>
         </visual>
         <collision>
            <origin xyz="0 0 0" rpy="0 0 0" />
            <geometry>
               <mesh filename="package://robots_description/meshes/Yumi/gripper/coarse/base.stl" />
            </geometry>
         </collision>
      </link>

      <link name="grasp_link" />

      <joint name="grasp_joint" type="fixed">
         <origin xyz="0 0.0 0.13" rpy="0 0 0" />
         <child link="grasp_link" />
         <parent link="${name}_base" />
      </joint>
      
      <xacro:if value="${fake_execution == 'true'}">
         <!-- joint between base and right finger -->
         <joint name="${name}_joint_r" type="prismatic">
            <parent link="${name}_base" />
            <child link="${name}_finger_r" />
            <origin xyz="0 -0.0065 0.0837" rpy="0 0 0" />
            <axis xyz="-1 0 0" />
            <limit lower="0" upper="0.025"
               effort="${max_gripper_effort}" velocity="${max_gripper_velocity}" />
            <dynamics damping="${gripper_joint_damping}" />
         </joint>

         <link name="${name}_finger_r">

            <inertial>
               <origin xyz="0 0 0" rpy="0 0 0" />
               <mass value="0.1" />
               <inertia ixx="0.01" ixy="0" ixz="0" iyy="0.01" iyz="0" izz="0.01" />
            </inertial>

            <visual>
               <origin xyz="0 0 0" rpy="0 0 0" />
               <geometry>
                  <mesh filename="package://robots_description/meshes/Yumi/gripper/finger.stl" />
               </geometry>
               <material name="Blue" />
            </visual>

            <collision>
               <origin xyz="0 0 0" rpy="0 0 0" />
               <geometry>
                  <mesh filename="package://robots_description/meshes/Yumi/gripper/coarse/finger.stl" />
               </geometry>
               <material name="Blue" />
            </collision>
         </link>

         <!-- joint between base and left finger -->
         <joint name="${name}_joint_l" type="prismatic">
            <parent link="${name}_base" />
            <child link="${name}_finger_l" />
            <origin xyz="0 0.0065 0.0837" rpy="0 0 ${PI}" />
            <axis xyz="-1 0 0" />
            <limit lower="0" upper="0.025"
               effort="${max_gripper_effort}" velocity="${max_gripper_velocity}" />
            <dynamics damping="${gripper_joint_damping}" />
         </joint>

         <link name="${name}_finger_l">
            <inertial>
               <origin xyz="0 0 0" rpy="0 0 0" />
               <mass value="0.1" />
               <inertia ixx="0.01" ixy="0" ixz="0" iyy="0.01" iyz="0" izz="0.01" />
            </inertial>

            <visual>
               <origin xyz="0 0 0" rpy="0 0 0" />
               <geometry>
                  <mesh filename="package://robots_description/meshes/Yumi/gripper/finger.stl" />
               </geometry>
               <material name="Blue" />
            </visual>

            <collision>
               <origin xyz="0 0 0" rpy="0 0 0" />
               <geometry>
                  <mesh filename="package://robots_description/meshes/Yumi/gripper/coarse/finger.stl" />
               </geometry>
               <material name="Blue" />
            </collision>
         </link>

         <!--Extensions -->
         <xacro:yumi_servo_gripper_transmission name="SmartGripper" hardware_interface="${hardware_interface}" />

         <gazebo reference="${parent}_joint">
            <disableFixedJointLumping>true</disableFixedJointLumping> 
            <preserveFixedJoint>true</preserveFixedJoint>
         </gazebo>

         <gazebo>
            <plugin name="gazebo_grasp_fix" filename="libgazebo_grasp_fix.so">
               <arm>
                  <arm_name>yumi</arm_name>
                  <palm_link>gripper_base</palm_link>
                  <gripper_link> gripper_finger_l </gripper_link>
                  <gripper_link> gripper_finger_r </gripper_link>
               </arm>
               <forces_angle_tolerance>100</forces_angle_tolerance>
               <update_rate>4</update_rate>
               <grip_count_threshold>4</grip_count_threshold>
               <max_grip_count>8</max_grip_count>
               <release_tolerance>0.002</release_tolerance>
               <disable_collisions_on_attach>false</disable_collisions_on_attach>
               <contact_topic>__default_topic__</contact_topic>
            </plugin>
         </gazebo>

      </xacro:if>
   
   </xacro:macro>

</robot>
